Workbook

Sheet Casos de prueba
A1: Matriz de Requerimiento de Pruebas – Piedrazul Citas App
A2: Elaboró: | B2: Grupo Piedrazul – Ingeniería de Sistemas | C2: Proyecto: | D2: Piedrazul – Sistema de agendamiento de citas médicas | E2: Versión: | F2: 1.0 | G2: Fecha: | H2: 2026-05-14
A3: Diseño | L3: 1ª Iteración | O3: 2ª Iteración | R3: 3ª Iteración
A4: Tipo de Caso | B4: Módulo | C4: Submódulo | D4: Componente | E4: ID del Caso | F4: Nombre del Caso | G4: Descripción de Paso | H4: Resultado Esperado | I4: Comentarios / Precondiciones | J4: Perfil de Usuario | K4: Aplica Aceptación | L4: Estado | M4: Observación | N4: Ejecuta | O4: Estado | P4: Observación | Q4: Ejecuta | R4: Estado | S4: Observación | T4: Ejecuta
A5: Sistema | B5: Portal Público | C5: Información del Centro | D5: Consulta de info | E5: PUB-01 | F5: Obtener información del centro médico | G5: El actor accede a GET /api/public/info sin credenciales | H5: El sistema retorna 200 OK con los campos: name, tagline, address, phone, attentionHours, about | I5: Sin precondiciones. El endpoint es público | J5: Anónimo | K5: X | L5: EA | N5: Juan Felipe Ramirez | O5: PDTE | R5: PDTE
A6: Sistema | B6: Portal Público | C6: Proveedores | D6: Listado de médicos activos | E6: PUB-02 | F6: Listar médicos/proveedores activos | G6: El actor realiza GET /api/public/providers | H6: El sistema retorna 200 OK con lista de proveedores activos (id, fullName, specialty, defaultSlotIntervalMinutes). Proveedores inactivos no aparecen. | I6: Debe existir al menos un proveedor activo en la BD | J6: Anónimo | K6: X | L6: EA | N6: Juan Felipe Ramirez | O6: PDTE | R6: PDTE
A7: Sistema | B7: Portal Público | C7: Disponibilidad | D7: Consultar slots disponibles | E7: PUB-03 | F7: Consultar disponibilidad de un médico en fecha válida | G7: El actor realiza GET /api/public/providers/{providerId}/availability?date=YYYY-MM-DD con fecha dentro de la ventana configurada | H7: El sistema retorna 200 OK con lista de slots (startTime, endTime, available). Los slots ya ocupados muestran available=false | I7: Proveedor existente con disponibilidad semanal configurada | J7: Anónimo | K7: X | L7: EA | N7: Juan Felipe Ramirez | O7: PDTE | R7: PDTE
A8: Sistema | B8: Portal Público | C8: Disponibilidad | D8: Fecha fuera de ventana | E8: PUB-04 | F8: Consultar disponibilidad con fecha fuera de la ventana de agendamiento | G8: El actor consulta disponibilidad con fecha superior a WeeksAheadBooking semanas | H8: El sistema retorna error de validación indicando que la fecha supera la ventana permitida | I8: WeeksAheadBooking = 6 semanas (configuración por defecto) | J8: Anónimo | L8: EA | N8: Juan Felipe Ramirez | O8: PDTE | R8: PDTE
A9: Sistema | B9: Portal Público | C9: Agendamiento | D9: Agendar cita como invitado | E9: PUB-05 | F9: Crear cita pública sin cuenta de paciente | G9: El actor realiza POST /api/public/appointments con datos completos: providerId, appointmentDate, startTime, documentNumber, firstName, lastName, phone, gender, bookAsGuest=true | H9: El sistema retorna 200 OK con la cita creada (id, providerName, startTime, status=Scheduled, channel=Web) | I9: Slot debe estar disponible. No debe existir otra cita del paciente en el mismo slot | J9: Anónimo | K9: X | L9: EA | N9: Juan Felipe Ramirez | O9: PDTE | R9: PDTE
A10: Sistema | B10: Portal Público | C10: Agendamiento | D10: Agendar cita en slot ocupado | E10: PUB-06 | F10: Intentar crear cita en un slot ya reservado | G10: El actor intenta agendar en un slot cuyo available=false | H10: El sistema retorna 409 Conflict indicando que el horario no está disponible | I10: Precondición: existe una cita programada en ese slot | J10: Anónimo | L10: ENA | M10: Reserva en slot ocupado responde 400 (esperado 409). | N10: Juan Felipe Ramirez | O10: PDTE | R10: PDTE
A11: Sistema | B11: Portal Público | C11: Agendamiento | D11: Validación de campos obligatorios | E11: PUB-07 | F11: Crear cita con campos requeridos vacíos (documentNumber vacío) | G11: POST /api/public/appointments sin documentNumber | H11: El sistema retorna 422 Unprocessable Entity con listado de errores de validación | I11: Sin precondiciones especiales | J11: Anónimo | L11: ENA | M11: Validacion responde 400 (esperado 422). | N11: Juan Felipe Ramirez | O11: PDTE | R11: PDTE
A12: Sistema | B12: Portal Público | C12: Búsqueda Pública | D12: Lookup de paciente existente | E12: PUB-08 | F12: Buscar paciente por número de documento (existe) | G12: GET /api/public/patients/lookup?document=1000000001 | H12: El sistema retorna exists=true con firstName, lastName, gender, BirthYear y datos enmascarados (maskedPhone, maskedEmail). NO retorna datos completos. | I12: Paciente con documento 1000000001 debe existir en la BD | J12: Anónimo | K12: X | L12: EA | N12: Juan Felipe Ramirez | O12: PDTE | R12: PDTE
A13: Sistema | B13: Portal Público | C13: Búsqueda Pública | D13: Lookup de paciente inexistente | E13: PUB-09 | F13: Buscar paciente con documento que no existe | G13: GET /api/public/patients/lookup?document=9999999999 | H13: El sistema retorna 200 OK con exists=false y todos los campos nulos | I13: Sin precondiciones | J13: Anónimo | L13: EA | N13: Juan Felipe Ramirez | O13: PDTE | R13: PDTE
A14: Sistema | B14: Autenticación | C14: Registro | D14: Registro de nueva cuenta paciente | E14: AUT-01 | F14: Registrar nueva cuenta de paciente con datos válidos | G14: El actor accede a /crear-cuenta, ingresa documentNumber, firstName, lastName, password válida y confirma registro | H14: Se crea la cuenta. El sistema redirige al portal de paciente con sesión activa. La contraseña se almacena con hash (no en texto plano). | I14: El documentNumber no debe existir previamente en la BD local | J14: Paciente | K14: X | L14: EA | M14: Cuenta creada con documento 1000000007. | N14: Juan Felipe Ramirez | O14: PDTE | R14: PDTE
A15: Sistema | B15: Autenticación | C15: Registro | D15: Registro con cédula duplicada | E15: AUT-02 | F15: Intentar registrar cuenta con cédula ya existente | G15: El actor intenta registrarse con documentNumber ya registrado | H15: El sistema muestra mensaje: 'Ya existe una cuenta con esa cédula. Inicia sesión para continuar.' | I15: Precondición: existe cuenta con ese documentNumber | J15: Paciente | L15: EA | M15: Mensaje de duplicado mostrado. | N15: Juan Felipe Ramirez | O15: PDTE | R15: PDTE
A16: Sistema | B16: Autenticación | C16: Login Paciente | D16: Inicio de sesión con credenciales correctas | E16: AUT-03 | F16: Iniciar sesión en portal paciente con cédula y contraseña válidas | G16: El actor ingresa a /iniciar-sesion, digita documentNumber y contraseña correctos | H16: El sistema crea sesión y redirige al portal /portal/paciente. La sesión persiste en localStorage. | I16: Cuenta de paciente activa existente | J16: Paciente | K16: X | L16: EA | M16: Redirige a /portal/paciente con sesion activa. | N16: Juan Felipe Ramirez | O16: PDTE | R16: PDTE
A17: Sistema | B17: Autenticación | C17: Login Paciente | D17: Inicio de sesión con contraseña incorrecta | E17: AUT-04 | F17: Intentar iniciar sesión con contraseña errónea | G17: El actor ingresa cédula válida pero contraseña incorrecta | H17: El sistema muestra: 'Cédula o contraseña incorrectas. Verifica tus datos e inténtalo de nuevo.' | I17: Cuenta de paciente activa existente | J17: Paciente | L17: EA | M17: Mensaje de credenciales incorrectas mostrado. | N17: Juan Felipe Ramirez | O17: PDTE | R17: PDTE
A18: Sistema | B18: Autenticación | C18: Login Interno | D18: Inicio de sesión de personal interno | E18: AUT-05 | F18: Iniciar sesión en portal interno con correo y contraseña válidos | G18: El actor accede a /portal/interno/login, ingresa email y contraseña de cuenta interna (Admin/Scheduler/Doctor) | H18: El sistema crea sesión interna y redirige a /portal/interno/citas con el rol correspondiente | I18: Cuenta interna activa. Credenciales demo: admin@piedrazul.local / Admin123* | J18: Admin | K18: X | L18: EA | M18: Redirige a /portal/interno/citas con rol Admin. | N18: Juan Felipe Ramirez | O18: PDTE | R18: PDTE
A19: Sistema | B19: Autenticación | C19: Recuperación | D19: Solicitar recuperación de contraseña | E19: AUT-06 | F19: Solicitar código de recuperación para cuenta existente | G19: El actor va a /olvide-mi-contrasena e ingresa su documentNumber | H19: El sistema genera y muestra un código de 6 dígitos con TTL de 15 minutos. El código queda almacenado en localStorage. | I19: Cuenta de paciente activa existente | J19: Paciente | K19: X | L19: EA | M19: Codigo temporal mostrado en UI (modo demo). | N19: Juan Felipe Ramirez | O19: PDTE | R19: PDTE
A20: Sistema | B20: Autenticación | C20: Recuperación | D20: Restablecer contraseña con código válido | E20: AUT-07 | F20: Restablecer contraseña usando el código recibido | G20: El actor va a /restablecer-contrasena, ingresa el identificador, el código y la nueva contraseña | H20: El sistema actualiza la contraseña (re-hasheada). El código es invalidado. El actor puede iniciar sesión con la nueva contraseña. | I20: Precondición: código activo generado en AUT-06 | J20: Paciente | K20: X | L20: EA | M20: Contrasena actualizada a Reset1234!; login OK. | N20: Juan Felipe Ramirez | O20: PDTE | R20: PDTE
A21: Sistema | B21: Autenticación | C21: Recuperación | D21: Restablecer con código expirado o inválido | E21: AUT-08 | F21: Intentar restablecer contraseña con código incorrecto | G21: El actor ingresa un código que no coincide o ha expirado | H21: El sistema muestra: 'El código de recuperación no es válido o ya expiró.' | I21: TTL del código: 15 minutos | J21: Paciente | L21: EA | M21: Mensaje de codigo invalido mostrado. | N21: Juan Felipe Ramirez | O21: PDTE | R21: PDTE
A22: Sistema | B22: Portal Paciente | C22: Perfil | D22: Ver perfil del paciente autenticado | E22: PAC-01 | F22: Consultar los datos de perfil del paciente autenticado | G22: El actor autenticado como Paciente accede a GET /api/patient/profile | H22: El sistema retorna 200 OK con documentNumber, firstName, lastName, phone, gender, birthDate, email, isGuest | I22: Sesión de paciente activa | J22: Paciente | K22: X | L22: EA | N22: Juan Felipe Ramirez | O22: PDTE | R22: PDTE
A23: Sistema | B23: Portal Paciente | C23: Perfil | D23: Actualizar datos del perfil | E23: PAC-02 | F23: Actualizar teléfono y fecha de nacimiento del perfil | G23: El actor autenticado realiza PUT /api/patient/profile con los datos modificados | H23: El sistema retorna 200 OK con los datos actualizados. La información persiste en BD. | I23: Sesión de paciente activa. Perfil previamente creado | J23: Paciente | K23: X | L23: EA | N23: Juan Felipe Ramirez | O23: PDTE | R23: PDTE
A24: Sistema | B24: Portal Paciente | C24: Mis Citas | D24: Listar citas del paciente | E24: PAC-03 | F24: Obtener todas las citas del paciente autenticado | G24: El actor autenticado realiza GET /api/patient/appointments | H24: El sistema retorna 200 OK con lista de citas del paciente (id, providerName, specialty, appointmentDate, startTime, status, channel) | I24: Paciente con al menos una cita programada | J24: Paciente | K24: X | L24: EA | N24: Juan Felipe Ramirez | O24: PDTE | R24: PDTE
A25: Sistema | B25: Portal Paciente | C25: Mis Citas | D25: Agendar cita con cuenta activa | E25: PAC-04 | F25: Crear cita desde portal de paciente autenticado | G25: El actor autenticado realiza POST /api/patient/appointments con datos válidos de slot disponible | H25: El sistema retorna 200 OK con la cita creada. La cita queda asociada al externalUserId del paciente. | I25: Slot disponible. Paciente con sesión activa | J25: Paciente | K25: X | L25: EA | N25: Juan Felipe Ramirez | O25: PDTE | R25: PDTE
A26: Sistema | B26: Portal Paciente | C26: Mis Citas | D26: Cancelar cita propia | E26: PAC-05 | F26: Cancelar una cita programada del paciente | G26: El actor autenticado realiza PATCH /api/patient/appointments/{id}/cancel | H26: El sistema retorna 200 OK con status=Cancelled. El paciente no puede cancelar citas de otro paciente. | I26: Cita con status=Scheduled perteneciente al paciente | J26: Paciente | K26: X | L26: EA | N26: Juan Felipe Ramirez | O26: PDTE | R26: PDTE
A27: Sistema | B27: Portal Paciente | C27: Mis Citas | D27: Cancelar cita de otro paciente | E27: PAC-06 | F27: Intentar cancelar una cita que no pertenece al paciente autenticado | G27: El actor autenticado intenta cancelar un appointmentId que pertenece a otro paciente | H27: El sistema retorna 403 Forbidden o 404 Not Found. La cita no es cancelada. | I27: Sesión de Paciente A activa. Cita perteneciente a Paciente B | J27: Paciente | L27: ENA | M27: Cancelacion de cita ajena responde 400 (esperado 403/404). | N27: Juan Felipe Ramirez | O27: PDTE | R27: PDTE
A28: Sistema | B28: Portal Interno | C28: Búsqueda de Paciente | D28: Buscar paciente por documento (interno) | E28: INT-01 | F28: Buscar paciente desde la vista interna por número de documento | G28: El actor interno (Admin/Scheduler/Doctor) realiza GET /api/internal/patients/search?document=1000 | H28: El sistema retorna lista de pacientes cuyo documentNumber contiene el término. Retorna scheduledAppointmentsCount y hasUserAccount. | I28: Personal interno autenticado | J28: Scheduler | K28: X | L28: EA | N28: Juan Felipe Ramirez | O28: PDTE | R28: PDTE
A29: Sistema | B29: Portal Interno | C29: Gestión de Citas | D29: Ver agenda por médico y fecha | E29: INT-02 | F29: Consultar todas las citas de un médico en una fecha específica | G29: El actor interno realiza GET /api/internal/appointments?providerId={id}&date=YYYY-MM-DD | H29: El sistema retorna 200 OK con providerName, specialty, appointmentDate, total y lista de citas con todos sus datos. | I29: Proveedor existente. Personal interno autenticado | J29: Doctor | K29: X | L29: EA | N29: Juan Felipe Ramirez | O29: PDTE | R29: PDTE
A30: Sistema | B30: Portal Interno | C30: Gestión de Citas | D30: Crear cita desde portal interno | E30: INT-03 | F30: Registrar una cita para un paciente desde el portal interno (canal WhatsApp o Teléfono) | G30: El actor (Scheduler) realiza POST /api/internal/appointments con channel=WhatsApp, datos del paciente y slot disponible | H30: El sistema retorna 200 OK con la cita creada y channel=WhatsApp. Si el paciente no existe en BD, se crea como perfil. | I30: Slot disponible. El canal debe ser WhatsApp, Phone o Internal | J30: Scheduler | K30: X | L30: EA | N30: Juan Felipe Ramirez | O30: PDTE | R30: PDTE
A31: Sistema | B31: Portal Interno | C31: Gestión de Citas | D31: Actualizar estado de cita | E31: INT-04 | F31: Marcar una cita como Completada | G31: El actor interno realiza PATCH /api/internal/appointments/{id}/status con body {status: 'Completada'} | H31: El sistema retorna 200 OK con status=Completada. El cambio queda auditado. | I31: Cita con status=Scheduled existente. Actor con rol Admin, Scheduler o Doctor | J31: Doctor | K31: X | L31: EA | M31: Se completo una cita pasada; validacion de fecha OK. | N31: Juan Felipe Ramirez | O31: PDTE | R31: PDTE
A32: Sistema | B32: Portal Interno | C32: Gestión de Citas | D32: Actualizar estado con valor inválido | E32: INT-05 | F32: Intentar actualizar estado con un valor no reconocido | G32: PATCH /api/internal/appointments/{id}/status con status='EstadoInventado' | H32: El sistema retorna 422 o 400 con error de validación. El estado de la cita no cambia. | I32: Cita existente. Actor con rol interno válido | J32: Scheduler | L32: EA | N32: Juan Felipe Ramirez | O32: PDTE | R32: PDTE
A33: Sistema | B33: Portal Interno | C33: Gestión de Citas | D33: Reprogramar una cita | E33: INT-06 | F33: Cambiar la fecha y hora de una cita existente | G33: El actor interno realiza PUT /api/internal/appointments/{id}/reschedule con newDate y newStartTime de un slot disponible | H33: El sistema retorna 200 OK con los nuevos datos. Se crea un registro en AppointmentHistory con los datos anteriores y el usuario que hizo el cambio. | I33: Cita con status=Scheduled. Nuevo slot disponible en el mismo proveedor | J33: Scheduler | K33: X | L33: EA | N33: Juan Felipe Ramirez | O33: PDTE | R33: PDTE
A34: Sistema | B34: Portal Interno | C34: Gestión de Citas | D34: Reprogramar a slot ocupado | E34: INT-07 | F34: Intentar reprogramar a un horario ya reservado | G34: PUT /api/internal/appointments/{id}/reschedule apuntando a slot con available=false | H34: El sistema retorna 409 Conflict indicando que el nuevo horario no está disponible | I34: Cita existente. Slot de destino ya ocupado | J34: Scheduler | L34: EA | N34: Juan Felipe Ramirez | O34: PDTE | R34: PDTE
A35: Sistema | B35: Portal Interno | C35: Historial | D35: Consultar historial de reprogramaciones | E35: INT-08 | F35: Ver el historial de cambios de una cita que fue reprogramada | G35: GET /api/internal/appointments/{id}/history | H35: El sistema retorna lista de AppointmentHistory con: previousDate/Time, newDate/Time, reason, changedBy, changedAtUtc | I35: Cita que haya sido reprogramada al menos una vez | J35: Doctor | K35: X | L35: EA | N35: Juan Felipe Ramirez | O35: PDTE | R35: PDTE
A36: Sistema | B36: Portal Interno | C36: Exportación | D36: Exportar agenda en PDF | E36: INT-09 | F36: Descargar el listado de citas de un médico en formato PDF | G36: GET /api/internal/appointments/export/pdf?providerId={id}&date=YYYY-MM-DD | H36: El sistema retorna 200 con Content-Type=application/pdf y el archivo citas-YYYYMMDD.pdf. El PDF contiene los datos de las citas del día. | I36: Deben existir citas para el proveedor y fecha indicados | J36: Admin | K36: X | L36: EA | N36: Juan Felipe Ramirez | O36: PDTE | R36: PDTE
A37: Sistema | B37: Portal Interno | C37: Exportación | D37: Exportar agenda en CSV | E37: INT-10 | F37: Descargar el listado de citas de un médico en formato CSV | G37: GET /api/internal/appointments/export/csv?providerId={id}&date=YYYY-MM-DD | H37: El sistema retorna 200 con Content-Type=text/csv y el archivo citas_YYYYMMDD.csv con encabezados y datos de citas. | I37: Deben existir citas para el proveedor y fecha indicados | J37: Admin | K37: X | L37: EA | N37: Juan Felipe Ramirez | O37: PDTE | R37: PDTE
A38: Sistema | B38: Portal Interno | C38: Exportación | D38: Exportar PDF sin citas | E38: INT-11 | F38: Intentar exportar PDF en fecha sin citas agendadas | G38: GET /api/internal/appointments/export/pdf con fecha sin citas | H38: El sistema retorna 404 Not Found con mensaje 'No fue posible generar el PDF solicitado.' | I38: Fecha sin citas para el proveedor indicado | J38: Admin | L38: ENA | M38: PDF sin citas responde 200 con archivo vacio (esperado 404). | N38: Juan Felipe Ramirez | O38: PDTE | R38: PDTE
A39: Sistema | B39: Portal Interno | C39: Control de Acceso | D39: Acceso sin autenticación al portal interno | E39: INT-12 | F39: Intentar acceder a endpoints internos sin token/sesión | G39: GET /api/internal/appointments sin cabecera de autenticación | H39: El sistema retorna 401 Unauthorized. El recurso no es accesible. | I39: Sin sesión activa | J39: Anónimo | K39: X | L39: EA | N39: Juan Felipe Ramirez | O39: PDTE | R39: PDTE
A40: Sistema | B40: Administración | C40: Configuración | D40: Ver configuración del sistema | E40: ADM-01 | F40: Consultar parámetros globales del sistema (semanas de agendamiento y zona horaria) | G40: El actor Admin o Doctor realiza GET /api/admin/settings | H40: El sistema retorna 200 OK con weeksAheadBooking (entero) y timeZoneId (ej. 'America/Bogota') | I40: Actor con rol Admin o Doctor | J40: Admin | K40: X | L40: EA | N40: Juan Felipe Ramirez | O40: PDTE | R40: PDTE
...

Sheet Datos de prueba
A1: Matriz de Requerimiento de Pruebas – Datos de Prueba
A3: ID Caso | B3: Paso | C3: Campo | D3: Valor / Dato de Prueba | E3: Observación
A4: PUB-05 | B4: 1 | C4: providerId | D4: <GUID del proveedor activo> | E4: Obtener de GET /api/public/providers
A5: PUB-05 | B5: 1 | C5: appointmentDate | D5: 2026-05-20 | E5: Fecha dentro de ventana de 6 semanas
A6: PUB-05 | B6: 1 | C6: startTime | D6: 09:00 | E6: Slot disponible
A7: PUB-05 | B7: 1 | C7: documentNumber | D7: 9876543210 | E7: Paciente nuevo
A8: PUB-05 | B8: 1 | C8: firstName | D8: Laura
A9: PUB-05 | B9: 1 | C9: lastName | D9: Martínez
A10: PUB-05 | B10: 1 | C10: phone | D10: 3001234567
A11: PUB-05 | B11: 1 | C11: gender | D11: Female
A12: PUB-05 | B12: 1 | C12: bookAsGuest | D12: true
A13: AUT-03 | B13: 1 | C13: documentNumber | D13: 1000000001 | E13: Cuenta demo seeded
A14: AUT-03 | B14: 1 | C14: password | D14: Paciente123* | E14: Contraseña hasheada en localStorage
A15: AUT-05 | B15: 1 | C15: email | D15: admin@piedrazul.local
A16: AUT-05 | B16: 1 | C16: password | D16: Admin123*
A17: INT-03 | B17: 1 | C17: providerId | D17: <GUID>
A18: INT-03 | B18: 1 | C18: appointmentDate | D18: 2026-05-21
A19: INT-03 | B19: 1 | C19: startTime | D19: 10:00
A20: INT-03 | B20: 1 | C20: documentNumber | D20: 1122334455
A21: INT-03 | B21: 1 | C21: firstName | D21: Carlos
A22: INT-03 | B22: 1 | C22: lastName | D22: Ruiz
A23: INT-03 | B23: 1 | C23: phone | D23: 3109876543
A24: INT-03 | B24: 1 | C24: gender | D24: Male
A25: INT-03 | B25: 1 | C25: channel | D25: WhatsApp | E25: Canales: Web, WhatsApp, Phone, Internal
A26: ADM-05 | B26: 1 | C26: firstName | D26: Ana
A27: ADM-05 | B27: 1 | C27: lastName | D27: Torres
A28: ADM-05 | B28: 1 | C28: specialty | D28: Medicina General
A29: ADM-05 | B29: 1 | C29: defaultSlotIntervalMinutes | D29: 30
A30: ADM-05 | B30: 1 | C30: weeklyAvailabilities[0].dayOfWeek | D30: 1 | E30: Lunes=1
A31: ADM-05 | B31: 1 | C31: weeklyAvailabilities[0].startTime | D31: 08:00
A32: ADM-05 | B32: 1 | C32: weeklyAvailabilities[0].endTime | D32: 17:00
A33: ADM-05 | B33: 1 | C33: weeklyAvailabilities[0].slotIntervalMinutes | D33: 30
A34: ADM-05 | B34: 1 | C34: weeklyAvailabilities[0].isActive | D34: true

Sheet Incidencias Verificación
A1: Matriz de Requerimiento de Pruebas – Incidencias Verificación
A2: Módulo | B2: ID del Caso | C2: Descripción de la NC (DONDE / CUANDO / HALLAZGO / SE ESPERA) | D2: Clasificación NC | E2: Requerimiento (ID Jira) | F2: Observación | G2: Iteración | H2: Responsable
C3: (Registrar aquí cada NC cuyo estado sea ENA) DONDE: <módulo/componente> CUANDO: <paso del caso de prueba> HALLAZGO: <comportamiento observado> SE ESPERA: <comportamiento esperado>

Sheet Resultados Iteraciones
A1: Resultados por Iteración – Piedrazul
A2: 1ª Iteración
A3: Req. Prueba | B3: Bloqueante | C3: Funcional | D3: Presentación | E3: Ejecutados | F3: EA | G3: ENA | H3: PDTE | I3: Correctitud | J3: Densidad NC | K3: Confiabilidad | L3: Completitud | M3: Ejecuta | N3: Fecha
A4: 45 | B4: 0 | C4: 0 | D4: 0 | E4: =COUNTA('Casos de prueba'!L5:L49) | F4: =COUNTIF('Casos de prueba'!L5:L49,"EA") | G4: =COUNTIF('Casos de prueba'!L5:L49,"ENA") | H4: =COUNTIF('Casos de prueba'!L5:L49,"PDTE") | I4: =IF(E4=0,0,F4/E4) | J4: =IF(E4=0,0,G4/E4) | K4: =1-J4 | L4: =IF(45=0,0,E4/45) | M4: Juan Felipe Ramirez | N4: 2026-05-14
A6: 2ª Iteración
A7: Req. Prueba | B7: Bloqueante | C7: Funcional | D7: Presentación | E7: Ejecutados | F7: EA | G7: ENA | H7: PDTE | I7: Correctitud | J7: Densidad NC | K7: Confiabilidad | L7: Completitud | M7: Ejecuta | N7: Fecha
A8: 45 | B8: 0 | C8: 0 | D8: 0 | E8: =COUNTA('Casos de prueba'!O5:O49) | F8: =COUNTIF('Casos de prueba'!O5:O49,"EA") | G8: =COUNTIF('Casos de prueba'!O5:O49,"ENA") | H8: =COUNTIF('Casos de prueba'!O5:O49,"PDTE") | I8: =IF(E8=0,0,F8/E8) | J8: =IF(E8=0,0,G8/E8) | K8: =1-J8 | L8: =IF(45=0,0,E8/45) | M8: Juan Felipe Ramirez | N8: 2026-05-14
A10: 3ª Iteración
A11: Req. Prueba | B11: Bloqueante | C11: Funcional | D11: Presentación | E11: Ejecutados | F11: EA | G11: ENA | H11: PDTE | I11: Correctitud | J11: Densidad NC | K11: Confiabilidad | L11: Completitud | M11: Ejecuta | N11: Fecha
A12: 45 | B12: 0 | C12: 0 | D12: 0 | E12: =COUNTA('Casos de prueba'!R5:R49) | F12: =COUNTIF('Casos de prueba'!R5:R49,"EA") | G12: =COUNTIF('Casos de prueba'!R5:R49,"ENA") | H12: =COUNTIF('Casos de prueba'!R5:R49,"PDTE") | I12: =IF(E12=0,0,F12/E12) | J12: =IF(E12=0,0,G12/E12) | K12: =1-J12 | L12: =IF(45=0,0,E12/45) | M12: Juan Felipe Ramirez | N12: 2026-05-14
A15: Umbrales mínimos de liberación: Correctitud ≥ 95% | Confiabilidad ≥ 95% | Completitud ≥ 95%

Sheet Certificado de Pruebas
A1: Matriz de Requerimiento de Pruebas – Certificado de Pruebas
A3: Ingeniero: | B3: <Nombre del docente / revisor>
A4: A quien va dirigido: | B4: Grupo de Pruebas de Software – FIET, Universidad del Cauca
A5: Área: | B5: Ingeniería de Sistemas
A6: Empresa / Proyecto: | B6: Piedrazul – Sistema de agendamiento de citas médicas (clínica Popayán)
A8: 1. PRODUCTO SOFTWARE
A9: Nombre del producto: | B9: Piedrazul – Citas App
A10: Versión: | B10: 1.0 (Iteración 1)
A11: Fecha: | B11: 2026-05-14
A12: Módulos: | B12: Portal Público | Autenticación | Portal Paciente | Portal Interno | Administración
A13: Cliente: | B13: Clínica Piedrazul – Popayán, Colombia
A15: 2. CONDICIONES DE LIBERACIÓN
A16: Criterio | B16: Descripción | C16: Mínimo
A17: Correctitud | B17: % de funcionalidades que se comportan según el resultado esperado | C17: 95%
A18: Completitud | B18: % de casos de prueba diseñados y ejecutados | C18: 95%
A19: Confiabilidad | B19: 100% Correctitud – Densidad de NC | C19: 95%
A21: 3. ALCANCE DE LAS PRUEBAS
A22: Módulo | B22: Casos de Prueba | C22: EA | D22: ENA | E22: PDTE | F22: Observación
A23: Portal Público | B23: 9 | C23: PDTE | D23: 0 | E23: 9
A24: Autenticación | B24: 8 | C24: PDTE | D24: 0 | E24: 8
A25: Portal Paciente | B25: 6 | C25: PDTE | D25: 0 | E25: 6
A26: Portal Interno | B26: 12 | C26: PDTE | D26: 0 | E26: 12
A27: Administración | B27: 10 | C27: PDTE | D27: 0 | E27: 10
A28: TOTAL | B28: =SUM(B23:B27)

Sheet Matriz de Validación
A1: Matriz de Validación (Pruebas de Aceptación) – Piedrazul
A3: Tipo | B3: Módulo | C3: Submódulo | D3: ID Caso | E3: Nombre del Caso | F3: Descripción de Paso | G3: Resultado Esperado | H3: Perfil | I3: Est. 1ª It. | J3: Obs. 1ª It. | K3: Ej. 1ª It. | L3: Est. 2ª It. | M3: Obs. 2ª It. | N3: Ej. 2ª It. | O3: Estado Final | P3: Observación Final
A4: Sistema | B4: Portal Público | C4: Información del Centro | D4: PUB-01 | E4: Obtener información del centro médico | F4: El actor accede a GET /api/public/info sin credenciales | G4: El sistema retorna 200 OK con los campos: name, tagline, address, phone, attentionHours, about | H4: Anónimo | I4: PDTE | L4: PDTE | O4: PDTE
A5: Sistema | B5: Portal Público | C5: Proveedores | D5: PUB-02 | E5: Listar médicos/proveedores activos | F5: El actor realiza GET /api/public/providers | G5: El sistema retorna 200 OK con lista de proveedores activos (id, fullName, specialty, defaultSlotIntervalMinutes). Proveedores inactivos no aparecen. | H5: Anónimo | I5: EA | K5: Juan Felipe Ramirez | L5: PDTE | O5: EA
A6: Sistema | B6: Portal Público | C6: Disponibilidad | D6: PUB-03 | E6: Consultar disponibilidad de un médico en fecha válida | F6: El actor realiza GET /api/public/providers/{providerId}/availability?date=YYYY-MM-DD con fecha dentro de la ventana configurada | G6: El sistema retorna 200 OK con lista de slots (startTime, endTime, available). Los slots ya ocupados muestran available=false | H6: Anónimo | I6: EA | K6: Juan Felipe Ramirez | L6: PDTE | O6: EA
A7: Sistema | B7: Portal Público | C7: Agendamiento | D7: PUB-05 | E7: Crear cita pública sin cuenta de paciente | F7: El actor realiza POST /api/public/appointments con datos completos: providerId, appointmentDate, startTime, documentNumber, firstName, lastName, phone, gender, bookAsGuest=true | G7: El sistema retorna 200 OK con la cita creada (id, providerName, startTime, status=Scheduled, channel=Web) | H7: Anónimo | I7: EA | K7: Juan Felipe Ramirez | L7: PDTE | O7: EA
A8: Sistema | B8: Portal Público | C8: Búsqueda Pública | D8: PUB-08 | E8: Buscar paciente por número de documento (existe) | F8: GET /api/public/patients/lookup?document=1000000001 | G8: El sistema retorna exists=true con firstName, lastName, gender, BirthYear y datos enmascarados (maskedPhone, maskedEmail). NO retorna datos completos. | H8: Anónimo | I8: EA | K8: Juan Felipe Ramirez | L8: PDTE | O8: EA
A9: Sistema | B9: Autenticación | C9: Registro | D9: AUT-01 | E9: Registrar nueva cuenta de paciente con datos válidos | F9: El actor accede a /crear-cuenta, ingresa documentNumber, firstName, lastName, password válida y confirma registro | G9: Se crea la cuenta. El sistema redirige al portal de paciente con sesión activa. La contraseña se almacena con hash (no en texto plano). | H9: Paciente | I9: EA | J9: Cuenta creada con documento 1000000007. | K9: Juan Felipe Ramirez | L9: PDTE | O9: EA | P9: Cuenta creada con documento 1000000007.
A10: Sistema | B10: Autenticación | C10: Login Paciente | D10: AUT-03 | E10: Iniciar sesión en portal paciente con cédula y contraseña válidas | F10: El actor ingresa a /iniciar-sesion, digita documentNumber y contraseña correctos | G10: El sistema crea sesión y redirige al portal /portal/paciente. La sesión persiste en localStorage. | H10: Paciente | I10: EA | J10: Redirige a /portal/paciente con sesion activa. | K10: Juan Felipe Ramirez | L10: PDTE | O10: EA | P10: Redirige a /portal/paciente con sesion activa.
A11: Sistema | B11: Autenticación | C11: Login Interno | D11: AUT-05 | E11: Iniciar sesión en portal interno con correo y contraseña válidos | F11: El actor accede a /portal/interno/login, ingresa email y contraseña de cuenta interna (Admin/Scheduler/Doctor) | G11: El sistema crea sesión interna y redirige a /portal/interno/citas con el rol correspondiente | H11: Admin | I11: EA | J11: Redirige a /portal/interno/citas con rol Admin. | K11: Juan Felipe Ramirez | L11: PDTE | O11: EA | P11: Redirige a /portal/interno/citas con rol Admin.
A12: Sistema | B12: Autenticación | C12: Recuperación | D12: AUT-06 | E12: Solicitar código de recuperación para cuenta existente | F12: El actor va a /olvide-mi-contrasena e ingresa su documentNumber | G12: El sistema genera y muestra un código de 6 dígitos con TTL de 15 minutos. El código queda almacenado en localStorage. | H12: Paciente | I12: EA | J12: Codigo temporal mostrado en UI (modo demo). | K12: Juan Felipe Ramirez | L12: PDTE | O12: EA | P12: Codigo temporal mostrado en UI (modo demo).
A13: Sistema | B13: Autenticación | C13: Recuperación | D13: AUT-07 | E13: Restablecer contraseña usando el código recibido | F13: El actor va a /restablecer-contrasena, ingresa el identificador, el código y la nueva contraseña | G13: El sistema actualiza la contraseña (re-hasheada). El código es invalidado. El actor puede iniciar sesión con la nueva contraseña. | H13: Paciente | I13: EA | J13: Contrasena actualizada a Reset1234!; login OK. | K13: Juan Felipe Ramirez | L13: PDTE | O13: EA | P13: Contrasena actualizada a Reset1234!; login OK.
A14: Sistema | B14: Portal Paciente | C14: Perfil | D14: PAC-01 | E14: Consultar los datos de perfil del paciente autenticado | F14: El actor autenticado como Paciente accede a GET /api/patient/profile | G14: El sistema retorna 200 OK con documentNumber, firstName, lastName, phone, gender, birthDate, email, isGuest | H14: Paciente | I14: EA | K14: Juan Felipe Ramirez | L14: PDTE | O14: EA
A15: Sistema | B15: Portal Paciente | C15: Perfil | D15: PAC-02 | E15: Actualizar teléfono y fecha de nacimiento del perfil | F15: El actor autenticado realiza PUT /api/patient/profile con los datos modificados | G15: El sistema retorna 200 OK con los datos actualizados. La información persiste en BD. | H15: Paciente | I15: EA | K15: Juan Felipe Ramirez | L15: PDTE | O15: EA
A16: Sistema | B16: Portal Paciente | C16: Mis Citas | D16: PAC-03 | E16: Obtener todas las citas del paciente autenticado | F16: El actor autenticado realiza GET /api/patient/appointments | G16: El sistema retorna 200 OK con lista de citas del paciente (id, providerName, specialty, appointmentDate, startTime, status, channel) | H16: Paciente | I16: EA | K16: Juan Felipe Ramirez | L16: PDTE | O16: EA
A17: Sistema | B17: Portal Paciente | C17: Mis Citas | D17: PAC-04 | E17: Crear cita desde portal de paciente autenticado | F17: El actor autenticado realiza POST /api/patient/appointments con datos válidos de slot disponible | G17: El sistema retorna 200 OK con la cita creada. La cita queda asociada al externalUserId del paciente. | H17: Paciente | I17: EA | K17: Juan Felipe Ramirez | L17: PDTE | O17: EA
A18: Sistema | B18: Portal Paciente | C18: Mis Citas | D18: PAC-05 | E18: Cancelar una cita programada del paciente | F18: El actor autenticado realiza PATCH /api/patient/appointments/{id}/cancel | G18: El sistema retorna 200 OK con status=Cancelled. El paciente no puede cancelar citas de otro paciente. | H18: Paciente | I18: EA | K18: Juan Felipe Ramirez | L18: PDTE | O18: EA
A19: Sistema | B19: Portal Interno | C19: Búsqueda de Paciente | D19: INT-01 | E19: Buscar paciente desde la vista interna por número de documento | F19: El actor interno (Admin/Scheduler/Doctor) realiza GET /api/internal/patients/search?document=1000 | G19: El sistema retorna lista de pacientes cuyo documentNumber contiene el término. Retorna scheduledAppointmentsCount y hasUserAccount. | H19: Scheduler | I19: EA | K19: Juan Felipe Ramirez | L19: PDTE | O19: EA
A20: Sistema | B20: Portal Interno | C20: Gestión de Citas | D20: INT-02 | E20: Consultar todas las citas de un médico en una fecha específica | F20: El actor interno realiza GET /api/internal/appointments?providerId={id}&date=YYYY-MM-DD | G20: El sistema retorna 200 OK con providerName, specialty, appointmentDate, total y lista de citas con todos sus datos. | H20: Doctor | I20: EA | K20: Juan Felipe Ramirez | L20: PDTE | O20: EA
A21: Sistema | B21: Portal Interno | C21: Gestión de Citas | D21: INT-03 | E21: Registrar una cita para un paciente desde el portal interno (canal WhatsApp o Teléfono) | F21: El actor (Scheduler) realiza POST /api/internal/appointments con channel=WhatsApp, datos del paciente y slot disponible | G21: El sistema retorna 200 OK con la cita creada y channel=WhatsApp. Si el paciente no existe en BD, se crea como perfil. | H21: Scheduler | I21: EA | K21: Juan Felipe Ramirez | L21: PDTE | O21: EA
A22: Sistema | B22: Portal Interno | C22: Gestión de Citas | D22: INT-04 | E22: Marcar una cita como Completada | F22: El actor interno realiza PATCH /api/internal/appointments/{id}/status con body {status: 'Completada'} | G22: El sistema retorna 200 OK con status=Completada. El cambio queda auditado. | H22: Doctor | I22: EA | J22: Se completo una cita pasada; validacion de fecha OK. | K22: Juan Felipe Ramirez | L22: PDTE | O22: EA | P22: Se completo una cita pasada; validacion de fecha OK.
A23: Sistema | B23: Portal Interno | C23: Gestión de Citas | D23: INT-06 | E23: Cambiar la fecha y hora de una cita existente | F23: El actor interno realiza PUT /api/internal/appointments/{id}/reschedule con newDate y newStartTime de un slot disponible | G23: El sistema retorna 200 OK con los nuevos datos. Se crea un registro en AppointmentHistory con los datos anteriores y el usuario que hizo el cambio. | H23: Scheduler | I23: EA | K23: Juan Felipe Ramirez | L23: PDTE | O23: EA
A24: Sistema | B24: Portal Interno | C24: Historial | D24: INT-08 | E24: Ver el historial de cambios de una cita que fue reprogramada | F24: GET /api/internal/appointments/{id}/history | G24: El sistema retorna lista de AppointmentHistory con: previousDate/Time, newDate/Time, reason, changedBy, changedAtUtc | H24: Doctor | I24: EA | K24: Juan Felipe Ramirez | L24: PDTE | O24: EA
A25: Sistema | B25: Portal Interno | C25: Exportación | D25: INT-09 | E25: Descargar el listado de citas de un médico en formato PDF | F25: GET /api/internal/appointments/export/pdf?providerId={id}&date=YYYY-MM-DD | G25: El sistema retorna 200 con Content-Type=application/pdf y el archivo citas-YYYYMMDD.pdf. El PDF contiene los datos de las citas del día. | H25: Admin | I25: EA | K25: Juan Felipe Ramirez | L25: PDTE | O25: EA
A26: Sistema | B26: Portal Interno | C26: Exportación | D26: INT-10 | E26: Descargar el listado de citas de un médico en formato CSV | F26: GET /api/internal/appointments/export/csv?providerId={id}&date=YYYY-MM-DD | G26: El sistema retorna 200 con Content-Type=text/csv y el archivo citas_YYYYMMDD.csv con encabezados y datos de citas. | H26: Admin | I26: EA | K26: Juan Felipe Ramirez | L26: PDTE | O26: EA
A27: Sistema | B27: Portal Interno | C27: Control de Acceso | D27: INT-12 | E27: Intentar acceder a endpoints internos sin token/sesión | F27: GET /api/internal/appointments sin cabecera de autenticación | G27: El sistema retorna 401 Unauthorized. El recurso no es accesible. | H27: Anónimo | I27: EA | K27: Juan Felipe Ramirez | L27: PDTE | O27: EA
A28: Sistema | B28: Administración | C28: Configuración | D28: ADM-01 | E28: Consultar parámetros globales del sistema (semanas de agendamiento y zona horaria) | F28: El actor Admin o Doctor realiza GET /api/admin/settings | G28: El sistema retorna 200 OK con weeksAheadBooking (entero) y timeZoneId (ej. 'America/Bogota') | H28: Admin | I28: EA | K28: Juan Felipe Ramirez | L28: PDTE | O28: EA
A29: Sistema | B29: Administración | C29: Configuración | D29: ADM-02 | E29: Modificar la ventana de agendamiento de 6 a 4 semanas | F29: El actor Admin realiza PUT /api/admin/settings con weeksAheadBooking=4 y timeZoneId válido | G29: El sistema retorna 200 OK con los nuevos parámetros. La nueva ventana impacta inmediatamente la disponibilidad pública. | H29: Admin | I29: EA | K29: Juan Felipe Ramirez | L29: PDTE | O29: EA
A30: Sistema | B30: Administración | C30: Horarios Médicos | D30: ADM-04 | E30: Obtener lista completa de médicos con su disponibilidad semanal | F30: GET /api/admin/provider-schedules | G30: El sistema retorna 200 OK con lista de ProviderScheduleResponse: providerId, providerName, specialty, defaultSlotIntervalMinutes, weeklyAvailabilities (con dayOfWeek, startTime, endTime, slotIntervalMinutes, isActive) | H30: Admin | I30: EA | K30: Juan Felipe Ramirez | L30: PDTE | O30: EA
A31: Sistema | B31: Administración | C31: Horarios Médicos | D31: ADM-05 | E31: Registrar un nuevo médico con disponibilidad semanal | F31: POST /api/admin/provider-schedules con firstName, lastName, specialty, defaultSlotIntervalMinutes y weeklyAvailabilities (lunes a viernes 8:00-17:00, 30 min) | G31: El sistema retorna 200 OK con el nuevo proveedor creado e ID generado. El proveedor aparece en el listado público de proveedores. | H31: Admin | I31: EA | K31: Juan Felipe Ramirez | L31: PDTE | O31: EA
A32: Sistema | B32: Administración | C32: Horarios Médicos | D32: ADM-06 | E32: Modificar la disponibilidad semanal de un proveedor existente (ampliar horario) | F32: PUT /api/admin/provider-schedules/{providerId} con nuevas WeeklyAvailabilities | G32: El sistema retorna 200 OK con el horario actualizado. Los slots disponibles en el sistema reflejan el nuevo horario. | H32: Admin | I32: EA | K32: Juan Felipe Ramirez | L32: PDTE | O32: EA
A33: Sistema | B33: Administración | C33: Horarios Médicos | D33: ADM-07 | E33: Eliminar un proveedor del sistema | F33: DELETE /api/admin/provider-schedules/{providerId} | G33: El sistema retorna 204 No Content. El proveedor desaparece del listado público. Solo rol Admin puede ejecutar. | H33: Admin | I33: ENA | J33: Proveedor permanece en listado; solo se elimina disponibilidad semanal. | K33: Juan Felipe Ramirez | L33: PDTE | O33: ENA | P33: Proveedor permanece en listado; solo se elimina disponibilidad semanal.
A34: Sistema | B34: Administración | C34: Gestión Pacientes | D34: ADM-08 | E34: Buscar paciente por nombre o documento desde el panel de Admin | F34: GET /api/admin/patients?term=Juan | G34: El sistema retorna lista de pacientes que coincidan con el término (nombre o documento). Incluye scheduledAppointmentsCount y hasUserAccount. | H34: Admin | I34: EA | K34: Juan Felipe Ramirez | L34: PDTE | O34: EA
A35: Sistema | B35: Administración | C35: Gestión Pacientes | D35: ADM-09 | E35: Corregir el número de teléfono de un paciente desde Admin | F35: PUT /api/admin/patients/{patientId} con datos actualizados | G35: El sistema retorna 200 OK con PatientLookupResponse actualizado. Los cambios son inmediatos en BD. | H35: Admin | I35: EA | K35: Juan Felipe Ramirez | L35: PDTE | O35: EA
A36: Sistema | B36: Administración | C36: Control de Acceso | D36: ADM-10 | E36: Intentar que un Scheduler acceda a endpoints exclusivos de Admin | F36: El actor Scheduler intenta DELETE /api/admin/provider-schedules/{id} | G36: El sistema retorna 403 Forbidden. El proveedor no es eliminado. | H36: Scheduler | I36: EA | K36: Juan Felipe Ramirez | L36: PDTE | O36: EA

Sheet Incidencias Validación
A1: Incidencias en Validación – Piedrazul
A2: Módulo | B2: ID Caso | C2: Descripción NC (DONDE/CUANDO/HALLAZGO/SE ESPERA) | D2: Clasificación NC | E2: ID Jira | F2: Observación | G2: Iteración | H2: Responsable
C3: (Registrar las NC de validación aquí)

Sheet Informe de Validación
A1: Informe de Resultados de Validación – Piedrazul
A2: Módulo/Submódulo | B2: Req. Prueba | C2: Bloqueante | D2: Crítica | E2: Mayor | F2: Menor | G2: Trivial | H2: Ejecutados | I2: EA | J2: ENA | K2: PDTE | L2: Correctitud | M2: Densidad NC | N2: Confiabilidad
A3: Portal Público | B3: 9 | C3: 0 | D3: 0 | E3: 0 | F3: 0 | G3: 0 | H3: 9 | I3: 7 | J3: 2 | K3: 0 | L3: =IF(H3=0,0,I3/H3) | M3: =IF(H3=0,0,J3/H3) | N3: =1-M3
A4: Autenticación | B4: 8 | C4: 0 | D4: 0 | E4: 0 | F4: 0 | G4: 0 | H4: 8 | I4: 8 | J4: 0 | K4: 0 | L4: =IF(H4=0,0,I4/H4) | M4: =IF(H4=0,0,J4/H4) | N4: =1-M4
A5: Portal Paciente | B5: 6 | C5: 0 | D5: 0 | E5: 0 | F5: 0 | G5: 0 | H5: 6 | I5: 5 | J5: 1 | K5: 0 | L5: =IF(H5=0,0,I5/H5) | M5: =IF(H5=0,0,J5/H5) | N5: =1-M5
A6: Portal Interno | B6: 12 | C6: 0 | D6: 0 | E6: 0 | F6: 0 | G6: 0 | H6: 12 | I6: 11 | J6: 1 | K6: 0 | L6: =IF(H6=0,0,I6/H6) | M6: =IF(H6=0,0,J6/H6) | N6: =1-M6
A7: Administración | B7: 10 | C7: 0 | D7: 0 | E7: 0 | F7: 0 | G7: 0 | H7: 10 | I7: 9 | J7: 1 | K7: 0 | L7: =IF(H7=0,0,I7/H7) | M7: =IF(H7=0,0,J7/H7) | N7: =1-M7
A8: TOTAL | B8: =SUM(B3:B7) | C8: =SUM(C3:C7) | D8: =SUM(D3:D7) | E8: =SUM(E3:E7) | F8: =SUM(F3:F7) | G8: =SUM(G3:G7) | H8: =SUM(H3:H7) | I8: =SUM(I3:I7) | ... K8: =SUM(K3:K7) | L8: =IF(H8=0,0,I8/H8) | M8: =IF(H8=0,0,J8/H8) | N8: =1-M8
A10: Resumen validacion (1a iteracion)
A11: Ejecuta | B11: Juan Felipe Ramirez | C11: Fecha | D11: 2026-05-15
A12: Casos totales | B12: 45
A13: Ejecutados | B13: 45
A14: EA | B14: 40
A15: ENA | B15: 5
A16: PDTE | B16: 0
A17: Correctitud | B17: 0.88888889
A18: Confiabilidad | B18: 0.88888889
A20: ENA (casos)
A21: PUB-06 | B21: Reserva en slot ocupado responde 400 (esperado 409).
A22: PUB-07 | B22: Validacion responde 400 (esperado 422).
A23: PAC-06 | B23: Cancelacion de cita ajena responde 400 (esperado 403/404).
A24: INT-11 | B24: PDF sin citas responde 200 con archivo vacio (esperado 404).
A25: ADM-07 | B25: Proveedor permanece en listado; solo se elimina disponibilidad semanal.
